/home/tsb/.local/lib/python3.10/site-packages/webdataset/compat.py:136: UserWarning: WebDataset(shardshuffle=...) is None; set explicitly to False or a number
  warnings.warn("WebDataset(shardshuffle=...) is None; set explicitly to False or a number")
Here???
Process ForkProcess-1:
Traceback (most recent call last):
  File "/usr/lib/python3.10/multiprocessing/process.py", line 314, in _bootstrap
    self.run()
  File "/usr/lib/python3.10/multiprocessing/process.py", line 108, in run
    self._target(*self._args, **self._kwargs)
  File "/usr/lib/python3.10/concurrent/futures/process.py", line 240, in _process_worker
    call_item = call_queue.get(block=True)
  File "/usr/lib/python3.10/multiprocessing/queues.py", line 103, in get
    res = self._recv_bytes()
  File "/usr/lib/python3.10/multiprocessing/connection.py", line 216, in recv_bytes
    buf = self._recv_bytes(maxlength)
  File "/usr/lib/python3.10/multiprocessing/connection.py", line 414, in _recv_bytes
    buf = self._recv(4)
  File "/usr/lib/python3.10/multiprocessing/connection.py", line 379, in _recv
    chunk = read(handle, remaining)
KeyboardInterrupt

During handling of the above exception, another exception occurred:

Traceback (most recent call last):
  File "/usr/lib/python3.10/multiprocessing/process.py", line 317, in _bootstrap
    util._exit_function()
  File "/usr/lib/python3.10/multiprocessing/util.py", line 357, in _exit_function
    p.join()
  File "/usr/lib/python3.10/multiprocessing/process.py", line 149, in join
    res = self._popen.wait(timeout)
  File "/usr/lib/python3.10/multiprocessing/popen_fork.py", line 43, in wait
    return self.poll(os.WNOHANG if timeout == 0.0 else 0)
  File "/usr/lib/python3.10/multiprocessing/popen_fork.py", line 27, in poll
    pid, sts = os.waitpid(self.pid, flag)
KeyboardInterrupt
